Workbook

Sheet global_freelancers_raw
A1: freelancer_ID | B1: name | C1: gender | D1: age | E1: country | F1: language | G1: primary_skill | H1: years_of_experience | I1: hourly_rate (USD) | J1: rating | K1: is_active | L1: client_satisfaction
A2: FL250001 | B2: Ms. Nicole Kidd | C2: f | D2: 52 | E2: Italy | F2: Italian | G2: Blockchain Development | H2: 11 | I2: 100 | K2: 0
A3: FL250002 | B3: Vanessa Garcia | C3: FEMALE | D3: 52 | E3: Australia | F3: English | G3: Mobile Apps | H3: 34 | I3: USD 100 | J3: 3.3 | K3: 1 | L3: 0.84
A4: FL250003 | B4: Juan Nelson | C4: male | D4: 53 | E4: Germany | F4: German | G4: Graphic Design | H4: 31 | I4: 50 | J4: 0 | K4: N | L4: 0.71
A5: FL250004 | B5: Amanda Spencer | C5: F | D5: 38 | E5: Australia | F5: English | G5: Web Development | H5: 4 | I5: $40 | J5: 1.5 | K5: N | L5: 0.9
A6: FL250005 | B6: Lynn Curtis DDS | C6: female | D6: 53 | E6: Germany | F6: German | G6: Web Development | H6: 27 | I6: 30 | J6: 4.8 | K6: 0 | L6: 0.83
A7: FL250006 | B7: Lisa Johnson | C7: female | D7: 59 | E7: Netherlands | F7: Dutch | G7: AI | H7: 14 | I7: $30 | J7: 2.4 | K7: False
A8: FL250007 | B8: Eric Myers | C8: m | D8: 52 | E8: Indonesia | F8: Indonesian | G8: Data Analysis | H8: 10 | I8: USD 75 | J8: 3.1 | K8: 0 | L8: 0.94
A9: FL250008 | B9: Ricky Graham | C9: male | D9: 43 | E9: Italy | F9: Italian | G9: Blockchain Development | H9: 14 | I9: USD 40 | J9: 4.6 | K9: False | L9: 0.94
A10: FL250009 | B10: Sean Martin | C10: male | D10: 26 | E10: United States | F10: English | G10: Blockchain Development | H10: 4 | J10: 4 | K10: True | L10: 0.76
A11: FL250010 | B11: Matthew Lloyd | C11: MALE | D11: 52 | E11: Turkey | F11: Turkish | G11: AI | H11: 22 | I11: $50 | K11: 1
A12: FL250011 | B12: Gavin Randall | C12: m | D12: 40 | E12: United Kingdom | F12: English | G12: Data Analysis | H12: 17 | I12: 40 | J12: 3.6 | K12: yes | L12: 0.77
A13: FL250012 | B13: Michelle Curtis | C13: FEMALE | D13: 55 | E13: Argentina | F13: Spanish | G13: UI/UX Design | H13: 15 | K13: Y | L13: 0.86
A14: FL250013 | B14: Alice Schneider | C14: Female | D14: 57 | E14: United Kingdom | F14: English | G14: Cybersecurity | H14: 18 | J14: 2 | K14: 0 | L14: 0.86
A15: FL250014 | B15: Phillip Shelton | C15: MALE | D15: 38 | E15: Argentina | F15: Spanish | G15: Graphic Design | H15: 20 | I15: USD 75 | J15: 2.9 | K15: 1 | L15: 0.93
A16: FL250015 | B16: Edward Ferguson | C16: MALE | D16: 50 | E16: Germany | F16: German | G16: Data Analysis | H16: 22 | I16: 75 | J16: 3.7 | K16: 1 | L16: 0.7
A17: FL250016 | B17: Wyatt Stout | C17: m | D17: 42 | E17: Japan | F17: Japanese | G17: Data Analysis | H17: 0 | I17: $30 | J17: 1.2 | K17: 0 | L17: 0.69
A18: FL250017 | B18: Laura Johnson | C18: Female | D18: 39 | E18: Australia | F18: English | G18: DevOps | H18: 13 | I18: $30 | J18: 2.5 | K18: False | L18: 0.6
A19: FL250018 | B19: Scott Burns | C19: M | D19: 56 | E19: India | F19: Hindi | G19: Blockchain Development | L19: 0.87
A20: FL250019 | B20: Tyler Aguirre | C20: Male | D20: 56 | E20: United States | F20: English | G20: UI/UX Design | H20: 31 | I20: USD 50 | J20: 1.1 | K20: N | L20: 0.75
A21: FL250020 | B21: Matthew Lawson | C21: Male | D21: 57 | E21: Italy | F21: Italian | G21: Web Development | H21: 3 | I21: USD 100 | J21: 1.8 | K21: yes | L21: 0.68
A22: FL250021 | B22: James Cherry | C22: Male | E22: Indonesia | F22: Indonesian | G22: AI | H22: 9 | I22: 50 | J22: 1.8 | K22: False | L22: 0.65
A23: FL250022 | B23: Samuel Sanford | C23: m | D23: 51 | E23: Japan | F23: Japanese | G23: DevOps | J23: 2.4 | K23: N | L23: 0.69
A24: FL250023 | B24: Cesar Greene | C24: m | D24: 51 | E24: Brazil | F24: Portuguese | G24: Cybersecurity | H24: 21 | I24: USD 30 | J24: 4.7 | K24: N
A25: FL250024 | B25: Melanie Carter | C25: female | D25: 51 | E25: South Korea | F25: Korean | G25: Machine Learning | H25: 15 | I25: $50 | J25: 1.3 | K25: 1 | L25: 1
A26: FL250025 | B26: Jennifer Martin | C26: f | D26: 54 | E26: Indonesia | F26: Indonesian | G26: Machine Learning | H26: 13 | I26: 75 | J26: 2.9 | L26: 92
A27: FL250026 | B27: Anna Mccann | C27: FEMALE | D27: 22 | E27: South Korea | F27: Korean | G27: DevOps | H27: 0 | I27: USD 30 | J27: 1.2 | K27: 1 | L27: 0.7
A28: FL250027 | B28: Marissa Bass | C28: female | D28: 34 | E28: Japan | F28: Japanese | G28: Blockchain Development | H28: 8 | I28: $20 | J28: 0 | K28: True | L28: 0.89
A29: FL250028 | B29: Alexis Day | C29: Female | D29: 36 | E29: Russia | F29: Russian | G29: Graphic Design | H29: 11 | J29: 1.8 | K29: Y | L29: 0.86
A30: FL250029 | B30: Megan Jones | C30: female | D30: 47 | E30: Canada | F30: English | G30: AI | H30: 22 | I30: 30 | J30: 1.3 | K30: 0 | L30: 0.62
A31: FL250030 | B31: Lori Smith | C31: FEMALE | D31: 41 | E31: Netherlands | F31: Dutch | G31: Data Analysis | H31: 14 | I31: USD 75 | J31: 1.2 | K31: 0
A32: FL250031 | B32: Eric Carpenter | C32: Male | D32: 22 | E32: Netherlands | F32: Dutch | G32: DevOps | H32: 4 | J32: 1 | K32: yes
A33: FL250032 | B33: Timothy Daniels | C33: Male | D33: 38 | E33: France | F33: French | G33: Machine Learning | H33: 19 | I33: USD 100 | J33: 4.2 | K33: N | L33: 0.68
A34: FL250033 | B34: Robert Nelson | C34: M | D34: 46 | E34: Egypt | F34: Arabic | G34: AI | H34: 9 | I34: 20 | J34: 1.4 | K34: True | L34: 0.76
A35: FL250034 | B35: Michael Anderson | C35: male | E35: South Korea | F35: Korean | G35: AI | H35: 9 | I35: 40 | J35: 2.4 | K35: yes | L35: 82
A36: FL250035 | B36: Jessica Snyder | C36: FEMALE | D36: 54 | E36: United States | F36: English | G36: Web Development | H36: 32 | I36: 75 | J36: 1 | K36: yes | L36: 0.81
A37: FL250036 | B37: Emily Daniels | C37: female | D37: 52 | E37: South Korea | F37: Korean | G37: Web Development | H37: 28 | I37: $20 | K37: 0
A38: FL250037 | B38: Jamie Ramirez | C38: f | D38: 42 | E38: Japan | F38: Japanese | G38: Mobile Apps | H38: 6 | I38: 40 | K38: 0 | L38: 0.63
A39: FL250038 | B39: Amy Harrison | C39: F | D39: 29 | E39: Netherlands | F39: Dutch | G39: Graphic Design | H39: 10 | I39: 40 | J39: 2.2 | K39: N | L39: 0.67
A40: FL250039 | B40: Melinda White | C40: F | D40: 42 | E40: South Africa | F40: Afrikaans | G40: Mobile Apps | H40: 23 | I40: 50 | J40: 3.2 | K40: yes
...

Sheet Sheet1
A1: freelancer_ID | B1: name | C1: First Name | D1: Last Name | E1: Full Name | H1: gender | I1: Proper Gender | J1: age | K1: Age Imputaion | L1: Age level | M1: country | N1: language | O1: primary_skill | P1: years_of_experience | Q1: Experience Imputation | R1: hourly_rate (USD) | U1: Hourly Rate Imputation | V1: Hourly Rate Imputation | W1: rating | X1: Rating Imputation | Y1: is_active | AA1: Is Active Imputation | AB1: Proper Is active | AC1: client_satisfaction | AD1: Client Satisfaction Imputation
A2: FL250001 | B2: Ms. Nicole Kidd | C2: Nicole | D2: Kidd | E2: =CONCATENATE(C2," ",D2) -> Nicole Kidd | F2: =PROPER(E2) -> Nicole Kidd | H2: Female | I2: =PROPER(H2) -> Female | J2: 52 | K2: =IF(ISBLANK(J2),ROUND(AVERAGEIF($I$2:$I$1001,I2,$J$2:$J$1001),0),J2) -> 52 | L2: =IF(AND(K2>=20,K2<=30),"First level",IF(AND(K2>30,K2<=40),"Second level",IF(AND(K2>40,K2<=50),"Third level",IF(H9>50,"Fourth level")))) -> Fourth level | M2: Italy | N2: Italian | O2: Blockchain Development | P2: 11 | Q2: =IF(ISBLANK(P2),ROUND(AVERAGEIF($L$2:$L$1001,L2,$P$2:$P$1001),0),P2) -> 11 | R2: 100 | S2: 100 | T2: 100 | U2: =IF(ISBLANK(T2),AVERAGE(T1:T1001),T2) -> 100 | V2: 100 | X2: =IF(ISBLANK(W2),AVERAGE(W2:W1001),W2) -> 2.5125695 | Y2: No | Z2: =CLEAN(TRIM(Y2)) -> No | AA2: =IF(ISBLANK(Z2),"Unknown",Z2) -> No | AB2: =PROPER(AA2) -> No | AD2: =IF(ISBLANK(AC2),AVERAGE(AC2:AC1001),AC2) -> 79.269417
A3: FL250002 | B3: Vanessa Garcia | C3: Vanessa | D3: Garcia | E3: =CONCATENATE(C3," ",D3) -> Vanessa Garcia | F3: =PROPER(E3) -> Vanessa Garcia | H3: FEMALE | I3: =PROPER(H3) -> Female | J3: 52 | K3: =IF(ISBLANK(J3),ROUND(AVERAGEIF($I$2:$I$1001,I3,$J$2:$J$1001),0),J3) -> 52 | L3: =IF(AND(K3>=20,K3<=30),"First level",IF(AND(K3>30,K3<=40),"Second level",IF(AND(K3>40,K3<=50),"Third level",IF(H10>50,"Fourth level")))) -> Fourth level | M3: Australia | N3: English | O3: Mobile Apps | P3: 34 | Q3: =IF(ISBLANK(P3),ROUND(AVERAGEIF($L$2:$L$1001,L3,$P$2:$P$1001),0),P3) -> 34 | R3: USD 100 | S3: 100 | T3: 100 | U3: =IF(ISBLANK(T3),AVERAGE(T2:T1002),T3) -> 100 | V3: 100 | W3: 3.3 | X3: =IF(ISBLANK(W3),AVERAGE(W3:W1002),W3) -> 3.3 | Y3: Yes | Z3: =CLEAN(TRIM(Y3)) -> Yes | AA3: =IF(ISBLANK(Z3),"Unknown",Z3) -> Yes | AB3: =PROPER(AA3) -> Yes | AC3: 84 | AD3: =IF(ISBLANK(AC3),AVERAGE(AC3:AC1002),AC3) -> 84 | AF3: Before filled (Blank Columns):
A4: FL250003 | B4: Juan Nelson | C4: Juan | D4: Nelson | E4: =CONCATENATE(C4," ",D4) -> Juan Nelson | F4: =PROPER(E4) -> Juan Nelson | H4: male | I4: =PROPER(H4) -> Male | J4: 53 | K4: =IF(ISBLANK(J4),ROUND(AVERAGEIF($I$2:$I$1001,I4,$J$2:$J$1001),0),J4) -> 53 | L4: =IF(AND(K4>=20,K4<=30),"First level",IF(AND(K4>30,K4<=40),"Second level",IF(AND(K4>40,K4<=50),"Third level",IF(H11>50,"Fourth level")))) -> Fourth level | M4: Germany | N4: German | O4: Graphic Design | P4: 31 | Q4: =IF(ISBLANK(P4),ROUND(AVERAGEIF($L$2:$L$1001,L4,$P$2:$P$1001),0),P4) -> 31 | R4: 50 | S4: 50 | T4: 50 | U4: =IF(ISBLANK(T4),AVERAGE(T3:T1003),T4) -> 50 | V4: 50 | W4: 0 | X4: =IF(ISBLANK(W4),AVERAGE(W4:W1003),W4) -> 0 | Y4: No | Z4: =CLEAN(TRIM(Y4)) -> No | AA4: =IF(ISBLANK(Z4),"Unknown",Z4) -> No | AB4: =PROPER(AA4) -> No | AC4: 71 | AD4: =IF(ISBLANK(AC4),AVERAGE(AC4:AC1003),AC4) -> 71 | AF4: freelancer_ID | AG4: 0
A5: FL250004 | B5: Amanda Spencer | C5: Amanda | D5: Spencer | E5: =CONCATENATE(C5," ",D5) -> Amanda Spencer | F5: =PROPER(E5) -> Amanda Spencer | H5: Female | I5: =PROPER(H5) -> Female | J5: 38 | K5: =IF(ISBLANK(J5),ROUND(AVERAGEIF($I$2:$I$1001,I5,$J$2:$J$1001),0),J5) -> 38 | L5: =IF(AND(K5>=20,K5<=30),"First level",IF(AND(K5>30,K5<=40),"Second level",IF(AND(K5>40,K5<=50),"Third level",IF(H12>50,"Fourth level")))) -> Second level | M5: Australia | N5: English | O5: Web Development | P5: 4 | Q5: =IF(ISBLANK(P5),ROUND(AVERAGEIF($L$2:$L$1001,L5,$P$2:$P$1001),0),P5) -> 4 | R5: $40 | S5: $40 | T5: 40 | U5: =IF(ISBLANK(T5),AVERAGE(T4:T1004),T5) -> 40 | V5: 40 | W5: 1.5 | X5: =IF(ISBLANK(W5),AVERAGE(W5:W1004),W5) -> 1.5 | Y5: No | Z5: =CLEAN(TRIM(Y5)) -> No | AA5: =IF(ISBLANK(Z5),"Unknown",Z5) -> No | AB5: =PROPER(AA5) -> No | AC5: 90 | AD5: =IF(ISBLANK(AC5),AVERAGE(AC5:AC1004),AC5) -> 90 | AF5: name | AG5: 0
A6: FL250005 | B6: Lynn Curtis DDS | C6: Lynn | D6: Curtis | E6: =CONCATENATE(C6," ",D6) -> Lynn Curtis | F6: =PROPER(E6) -> Lynn Curtis | H6: female | I6: =PROPER(H6) -> Female | J6: 53 | K6: =IF(ISBLANK(J6),ROUND(AVERAGEIF($I$2:$I$1001,I6,$J$2:$J$1001),0),J6) -> 53 | L6: =IF(AND(K6>=20,K6<=30),"First level",IF(AND(K6>30,K6<=40),"Second level",IF(AND(K6>40,K6<=50),"Third level",IF(H13>50,"Fourth level")))) -> Fourth level | M6: Germany | N6: German | O6: Web Development | P6: 27 | Q6: =IF(ISBLANK(P6),ROUND(AVERAGEIF($L$2:$L$1001,L6,$P$2:$P$1001),0),P6) -> 27 | R6: 30 | S6: 30 | T6: 30 | U6: =IF(ISBLANK(T6),AVERAGE(T5:T1005),T6) -> 30 | V6: 30 | W6: 4.8 | X6: =IF(ISBLANK(W6),AVERAGE(W6:W1005),W6) -> 4.8 | Y6: No | Z6: =CLEAN(TRIM(Y6)) -> No | AA6: =IF(ISBLANK(Z6),"Unknown",Z6) -> No | AB6: =PROPER(AA6) -> No | AC6: 83 | AD6: =IF(ISBLANK(AC6),AVERAGE(AC6:AC1005),AC6) -> 83 | AF6: gender | AG6: 0
A7: FL250006 | B7: Lisa Johnson | C7: Lisa | D7: Johnson | E7: =CONCATENATE(C7," ",D7) -> Lisa Johnson | F7: =PROPER(E7) -> Lisa Johnson | H7: female | I7: =PROPER(H7) -> Female | J7: 59 | K7: =IF(ISBLANK(J7),ROUND(AVERAGEIF($I$2:$I$1001,I7,$J$2:$J$1001),0),J7) -> 59 | L7: =IF(AND(K7>=20,K7<=30),"First level",IF(AND(K7>30,K7<=40),"Second level",IF(AND(K7>40,K7<=50),"Third level",IF(H14>50,"Fourth level")))) -> Fourth level | M7: Netherlands | N7: Dutch | O7: AI | P7: 14 | Q7: =IF(ISBLANK(P7),ROUND(AVERAGEIF($L$2:$L$1001,L7,$P$2:$P$1001),0),P7) -> 14 | R7: $30 | S7: $30 | T7: 30 | U7: =IF(ISBLANK(T7),AVERAGE(T6:T1006),T7) -> 30 | V7: 30 | W7: 2.4 | X7: =IF(ISBLANK(W7),AVERAGE(W7:W1006),W7) -> 2.4 | Y7: No | Z7: =CLEAN(TRIM(Y7)) -> No | AA7: =IF(ISBLANK(Z7),"Unknown",Z7) -> No | AB7: =PROPER(AA7) -> No | AD7: =IF(ISBLANK(AC7),AVERAGE(AC7:AC1006),AC7) -> 79.256098 | AF7: age | AG7: 30
A8: FL250007 | B8: Eric Myers | C8: Eric | D8: Myers | E8: =CONCATENATE(C8," ",D8) -> Eric Myers | F8: =PROPER(E8) -> Eric Myers | H8: Male | I8: =PROPER(H8) -> Male | J8: 52 | K8: =IF(ISBLANK(J8),ROUND(AVERAGEIF($I$2:$I$1001,I8,$J$2:$J$1001),0),J8) -> 52 | L8: =IF(AND(K8>=20,K8<=30),"First level",IF(AND(K8>30,K8<=40),"Second level",IF(AND(K8>40,K8<=50),"Third level",IF(H15>50,"Fourth level")))) -> Fourth level | M8: Indonesia | N8: Indonesian | O8: Data Analysis | P8: 10 | Q8: =IF(ISBLANK(P8),ROUND(AVERAGEIF($L$2:$L$1001,L8,$P$2:$P$1001),0),P8) -> 10 | R8: USD 75 | S8: 75 | T8: 75 | U8: =IF(ISBLANK(T8),AVERAGE(T7:T1007),T8) -> 75 | V8: 75 | W8: 3.1 | X8: =IF(ISBLANK(W8),AVERAGE(W8:W1007),W8) -> 3.1 | Y8: No | Z8: =CLEAN(TRIM(Y8)) -> No | AA8: =IF(ISBLANK(Z8),"Unknown",Z8) -> No | AB8: =PROPER(AA8) -> No | AC8: 94 | AD8: =IF(ISBLANK(AC8),AVERAGE(AC8:AC1007),AC8) -> 94 | AF8: country | AG8: 0
A9: FL250008 | B9: Ricky Graham | C9: Ricky | D9: Graham | E9: =CONCATENATE(C9," ",D9) -> Ricky Graham | F9: =PROPER(E9) -> Ricky Graham | H9: male | I9: =PROPER(H9) -> Male | J9: 43 | K9: =IF(ISBLANK(J9),ROUND(AVERAGEIF($I$2:$I$1001,I9,$J$2:$J$1001),0),J9) -> 43 | L9: =IF(AND(K9>=20,K9<=30),"First level",IF(AND(K9>30,K9<=40),"Second level",IF(AND(K9>40,K9<=50),"Third level",IF(H16>50,"Fourth level")))) -> Third level | M9: Italy | N9: Italian | O9: Blockchain Development | P9: 14 | Q9: =IF(ISBLANK(P9),ROUND(AVERAGEIF($L$2:$L$1001,L9,$P$2:$P$1001),0),P9) -> 14 | R9: USD 40 | S9: 40 | T9: 40 | U9: =IF(ISBLANK(T9),AVERAGE(T8:T1008),T9) -> 40 | V9: 40 | W9: 4.6 | X9: =IF(ISBLANK(W9),AVERAGE(W9:W1008),W9) -> 4.6 | Y9: No | Z9: =CLEAN(TRIM(Y9)) -> No | AA9: =IF(ISBLANK(Z9),"Unknown",Z9) -> No | AB9: =PROPER(AA9) -> No | AC9: 94 | AD9: =IF(ISBLANK(AC9),AVERAGE(AC9:AC1008),AC9) -> 94 | AF9: language | AG9: 0
A10: FL250009 | B10: Sean Martin | C10: Sean | D10: Martin | E10: =CONCATENATE(C10," ",D10) -> Sean Martin | F10: =PROPER(E10) -> Sean Martin | H10: male | I10: =PROPER(H10) -> Male | J10: 26 | K10: =IF(ISBLANK(J10),ROUND(AVERAGEIF($I$2:$I$1001,I10,$J$2:$J$1001),0),J10) -> 26 | L10: =IF(AND(K10>=20,K10<=30),"First level",IF(AND(K10>30,K10<=40),"Second level",IF(AND(K10>40,K10<=50),"Third level",IF(H17>50,"Fourth level")))) -> First level | M10: United States | N10: English | O10: Blockchain Development | P10: 4 | Q10: =IF(ISBLANK(P10),ROUND(AVERAGEIF($L$2:$L$1001,L10,$P$2:$P$1001),0),P10) -> 4 | U10: =IF(ISBLANK(T10),AVERAGE(T9:T1009),T10) -> 52.397108 | V10: 52.397108 | W10: 4 | X10: =IF(ISBLANK(W10),AVERAGE(W10:W1009),W10) -> 4 | Y10: Yes | Z10: =CLEAN(TRIM(Y10)) -> Yes | AA10: =IF(ISBLANK(Z10),"Unknown",Z10) -> Yes | AB10: =PROPER(AA10) -> Yes | AC10: 76 | AD10: =IF(ISBLANK(AC10),AVERAGE(AC10:AC1009),AC10) -> 76 | AF10: primary_skill | AG10: 0
A11: FL250010 | B11: Matthew Lloyd | C11: Matthew | D11: Lloyd | E11: =CONCATENATE(C11," ",D11) -> Matthew Lloyd | F11: =PROPER(E11) -> Matthew Lloyd | H11: MALE | I11: =PROPER(H11) -> Male | J11: 52 | K11: =IF(ISBLANK(J11),ROUND(AVERAGEIF($I$2:$I$1001,I11,$J$2:$J$1001),0),J11) -> 52 | L11: =IF(AND(K11>=20,K11<=30),"First level",IF(AND(K11>30,K11<=40),"Second level",IF(AND(K11>40,K11<=50),"Third level",IF(H18>50,"Fourth level")))) -> Fourth level | M11: Turkey | N11: Turkish | O11: AI | P11: 22 | Q11: =IF(ISBLANK(P11),ROUND(AVERAGEIF($L$2:$L$1001,L11,$P$2:$P$1001),0),P11) -> 22 | R11: $50 | S11: $50 | T11: 50 | U11: =IF(ISBLANK(T11),AVERAGE(T2:T1010),T11) -> 50 | V11: 50 | X11: =IF(ISBLANK(W11),AVERAGE(W11:W1010),W11) -> 2.5085297 | Y11: Yes | Z11: =CLEAN(TRIM(Y11)) -> Yes | AA11: =IF(ISBLANK(Z11),"Unknown",Z11) -> Yes | AB11: =PROPER(AA11) -> Yes | AD11: =IF(ISBLANK(AC11),AVERAGE(AC11:AC1010),AC11) -> 79.22399 | AF11: years_of_experience | AG11: 51
A12: FL250011 | B12: Gavin Randall | C12: Gavin | D12: Randall | E12: =CONCATENATE(C12," ",D12) -> Gavin Randall | F12: =PROPER(E12) -> Gavin Randall | H12: Male | I12: =PROPER(H12) -> Male | J12: 40 | K12: =IF(ISBLANK(J12),ROUND(AVERAGEIF($I$2:$I$1001,I12,$J$2:$J$1001),0),J12) -> 40 | L12: =IF(AND(K12>=20,K12<=30),"First level",IF(AND(K12>30,K12<=40),"Second level",IF(AND(K12>40,K12<=50),"Third level",IF(H19>50,"Fourth level")))) -> Second level | M12: United Kingdom | N12: English | O12: Data Analysis | P12: 17 | Q12: =IF(ISBLANK(P12),ROUND(AVERAGEIF($L$2:$L$1001,L12,$P$2:$P$1001),0),P12) -> 17 | R12: 40 | S12: 40 | T12: 40 | U12: =IF(ISBLANK(T12),AVERAGE(T11:T1011),T12) -> 40 | V12: 40 | W12: 3.6 | X12: =IF(ISBLANK(W12),AVERAGE(W12:W1011),W12) -> 3.6 | Y12: yes | Z12: =CLEAN(TRIM(Y12)) -> yes | AA12: =IF(ISBLANK(Z12),"Unknown",Z12) -> yes | AB12: =PROPER(AA12) -> Yes | AC12: 77 | AD12: =IF(ISBLANK(AC12),AVERAGE(AC12:AC1011),AC12) -> 77 | AF12: hourly_rate (USD) | AG12: 94
A13: FL250012 | B13: Michelle Curtis | C13: Michelle | D13: Curtis | E13: =CONCATENATE(C13," ",D13) -> Michelle Curtis | F13: =PROPER(E13) -> Michelle Curtis | H13: FEMALE | I13: =PROPER(H13) -> Female | J13: 55 | K13: =IF(ISBLANK(J13),ROUND(AVERAGEIF($I$2:$I$1001,I13,$J$2:$J$1001),0),J13) -> 55 | L13: =IF(AND(K13>=20,K13<=30),"First level",IF(AND(K13>30,K13<=40),"Second level",IF(AND(K13>40,K13<=50),"Third level",IF(H20>50,"Fourth level")))) -> Fourth level | M13: Argentina | N13: Spanish | O13: UI/UX Design | P13: 15 | Q13: =IF(ISBLANK(P13),ROUND(AVERAGEIF($L$2:$L$1001,L13,$P$2:$P$1001),0),P13) -> 15 | U13: =IF(ISBLANK(T13),AVERAGE(T12:T1012),T13) -> 52.413601 | V13: 52.413601 | X13: =IF(ISBLANK(W13),AVERAGE(W13:W1012),W13) -> 2.5073034 | Y13: Yes | Z13: =CLEAN(TRIM(Y13)) -> Yes | AA13: =IF(ISBLANK(Z13),"Unknown",Z13) -> Yes | AB13: =PROPER(AA13) -> Yes | AC13: 86 | AD13: =IF(ISBLANK(AC13),AVERAGE(AC13:AC1012),AC13) -> 86 | AF13: rating | AG13: 101
A14: FL250013 | B14: Alice Schneider | C14: Alice | D14: Schneider | E14: =CONCATENATE(C14," ",D14) -> Alice Schneider | F14: =PROPER(E14) -> Alice Schneider | H14: Female | I14: =PROPER(H14) -> Female | J14: 57 | K14: =IF(ISBLANK(J14),ROUND(AVERAGEIF($I$2:$I$1001,I14,$J$2:$J$1001),0),J14) -> 57 | L14: =IF(AND(K14>=20,K14<=30),"First level",IF(AND(K14>30,K14<=40),"Second level",IF(AND(K14>40,K14<=50),"Third level",IF(H21>50,"Fourth level")))) -> Fourth level | M14: United Kingdom | N14: English | O14: Cybersecurity | P14: 18 | Q14: =IF(ISBLANK(P14),ROUND(AVERAGEIF($L$2:$L$1001,L14,$P$2:$P$1001),0),P14) -> 18 | U14: =IF(ISBLANK(T14),AVERAGE(T13:T1013),T14) -> 52.427455 | V14: 52.427455 | W14: 2 | X14: =IF(ISBLANK(W14),AVERAGE(W14:W1013),W14) -> 2 | Y14: No | Z14: =CLEAN(TRIM(Y14)) -> No | AA14: =IF(ISBLANK(Z14),"Unknown",Z14) -> No | AB14: =PROPER(AA14) -> No | AC14: 86 | AD14: =IF(ISBLANK(AC14),AVERAGE(AC14:AC1013),AC14) -> 86 | AF14: is_active | AG14: 89
A15: FL250014 | B15: Phillip Shelton | C15: Phillip | D15: Shelton | E15: =CONCATENATE(C15," ",D15) -> Phillip Shelton | F15: =PROPER(E15) -> Phillip Shelton | H15: MALE | I15: =PROPER(H15) -> Male | J15: 38 | K15: =IF(ISBLANK(J15),ROUND(AVERAGEIF($I$2:$I$1001,I15,$J$2:$J$1001),0),J15) -> 38 | L15: =IF(AND(K15>=20,K15<=30),"First level",IF(AND(K15>30,K15<=40),"Second level",IF(AND(K15>40,K15<=50),"Third level",IF(H22>50,"Fourth level")))) -> Second level | M15: Argentina | N15: Spanish | O15: Graphic Design | P15: 20 | Q15: =IF(ISBLANK(P15),ROUND(AVERAGEIF($L$2:$L$1001,L15,$P$2:$P$1001),0),P15) -> 20 | R15: USD 75 | S15: 75 | T15: 75 | U15: =IF(ISBLANK(T15),AVERAGE(T14:T1014),T15) -> 75 | V15: 75 | W15: 2.9 | X15: =IF(ISBLANK(W15),AVERAGE(W15:W1014),W15) -> 2.9 | Y15: Yes | Z15: =CLEAN(TRIM(Y15)) -> Yes | AA15: =IF(ISBLANK(Z15),"Unknown",Z15) -> Yes | AB15: =PROPER(AA15) -> Yes | AC15: 93 | AD15: =IF(ISBLANK(AC15),AVERAGE(AC15:AC1014),AC15) -> 93 | AF15: client_satisfaction | AG15: 176
A16: FL250015 | B16: Edward Ferguson | C16: Edward | D16: Ferguson | E16: =CONCATENATE(C16," ",D16) -> Edward Ferguson | F16: =PROPER(E16) -> Edward Ferguson | H16: MALE | I16: =PROPER(H16) -> Male | J16: 50 | K16: =IF(ISBLANK(J16),ROUND(AVERAGEIF($I$2:$I$1001,I16,$J$2:$J$1001),0),J16) -> 50 | L16: =IF(AND(K16>=20,K16<=30),"First level",IF(AND(K16>30,K16<=40),"Second level",IF(AND(K16>40,K16<=50),"Third level",IF(H23>50,"Fourth level")))) -> Third level | M16: Germany | N16: German | O16: Data Analysis | P16: 22 | Q16: =IF(ISBLANK(P16),ROUND(AVERAGEIF($L$2:$L$1001,L16,$P$2:$P$1001),0),P16) -> 22 | R16: 75 | S16: 75 | T16: 75 | U16: =IF(ISBLANK(T16),AVERAGE(T15:T1015),T16) -> 75 | V16: 75 | W16: 3.7 | X16: =IF(ISBLANK(W16),AVERAGE(W16:W1015),W16) -> 3.7 | Y16: Yes | Z16: =CLEAN(TRIM(Y16)) -> Yes | AA16: =IF(ISBLANK(Z16),"Unknown",Z16) -> Yes | AB16: =PROPER(AA16) -> Yes | AC16: 70 | AD16: =IF(ISBLANK(AC16),AVERAGE(AC16:AC1015),AC16) -> 70
A17: FL250016 | B17: Wyatt Stout | C17: Wyatt | D17: Stout | E17: =CONCATENATE(C17," ",D17) -> Wyatt Stout | F17: =PROPER(E17) -> Wyatt Stout | H17: Male | I17: =PROPER(H17) -> Male | J17: 42 | K17: =IF(ISBLANK(J17),ROUND(AVERAGEIF($I$2:$I$1001,I17,$J$2:$J$1001),0),J17) -> 42 | L17: =IF(AND(K17>=20,K17<=30),"First level",IF(AND(K17>30,K17<=40),"Second level",IF(AND(K17>40,K17<=50),"Third level",IF(H24>50,"Fourth level")))) -> Third level | M17: Japan | N17: Japanese | O17: Data Analysis | P17: 0 | Q17: =IF(ISBLANK(P17),ROUND(AVERAGEIF($L$2:$L$1001,L17,$P$2:$P$1001),0),P17) -> 0 | R17: $30 | S17: $30 | T17: 30 | U17: =IF(ISBLANK(T17),AVERAGE(T16:T1016),T17) -> 30 | V17: 30 | W17: 1.2 | X17: =IF(ISBLANK(W17),AVERAGE(W17:W1016),W17) -> 1.2 | Y17: No | Z17: =CLEAN(TRIM(Y17)) -> No | AA17: =IF(ISBLANK(Z17),"Unknown",Z17) -> No | AB17: =PROPER(AA17) -> No | AC17: 69 | AD17: =IF(ISBLANK(AC17),AVERAGE(AC17:AC1016),AC17) -> 69
A18: FL250017 | B18: Laura Johnson | C18: Laura | D18: Johnson | E18: =CONCATENATE(C18," ",D18) -> Laura Johnson | F18: =PROPER(E18) -> Laura Johnson | H18: Female | I18: =PROPER(H18) -> Female | J18: 39 | K18: =IF(ISBLANK(J18),ROUND(AVERAGEIF($I$2:$I$1001,I18,$J$2:$J$1001),0),J18) -> 39 | L18: =IF(AND(K18>=20,K18<=30),"First level",IF(AND(K18>30,K18<=40),"Second level",IF(AND(K18>40,K18<=50),"Third level",IF(H25>50,"Fourth level")))) -> Second level | M18: Australia | N18: English | O18: DevOps | P18: 13 | Q18: =IF(ISBLANK(P18),ROUND(AVERAGEIF($L$2:$L$1001,L18,$P$2:$P$1001),0),P18) -> 13 | R18: $30 | S18: $30 | T18: 30 | U18: =IF(ISBLANK(T18),AVERAGE(T17:T1017),T18) -> 30 | V18: 30 | W18: 2.5 | X18: =IF(ISBLANK(W18),AVERAGE(W18:W1017),W18) -> 2.5 | Y18: No | Z18: =CLEAN(TRIM(Y18)) -> No | AA18: =IF(ISBLANK(Z18),"Unknown",Z18) -> No | AB18: =PROPER(AA18) -> No | AC18: 60 | AD18: =IF(ISBLANK(AC18),AVERAGE(AC18:AC1017),AC18) -> 60
A19: FL250018 | B19: Scott Burns | C19: Scott | D19: Burns | E19: =CONCATENATE(C19," ",D19) -> Scott Burns | F19: =PROPER(E19) -> Scott Burns | H19: Male | I19: =PROPER(H19) -> Male | J19: 56 | K19: =IF(ISBLANK(J19),ROUND(AVERAGEIF($I$2:$I$1001,I19,$J$2:$J$1001),0),J19) -> 56 | L19: =IF(AND(K19>=20,K19<=30),"First level",IF(AND(K19>30,K19<=40),"Second level",IF(AND(K19>40,K19<=50),"Third level",IF(H26>50,"Fourth level")))) -> Fourth level | M19: India | N19: Hindi | O19: Blockchain Development | Q19: =IF(ISBLANK(P19),ROUND(AVERAGEIF($L$2:$L$1001,L19,$P$2:$P$1001),0),P19) -> 19 | U19: =IF(ISBLANK(T19),AVERAGE(T18:T1018),T19) -> 52.402016 | V19: 52.402016 | X19: =IF(ISBLANK(W19),AVERAGE(W19:W1018),W19) -> 2.5075706 | AA19: =IF(ISBLANK(Z19),"Unknown",Z19) -> Unknown | AB19: =PROPER(AA19) -> Unknown | AC19: 87 | AD19: =IF(ISBLANK(AC19),AVERAGE(AC19:AC1018),AC19) -> 87
A20: FL250019 | B20: Tyler Aguirre | C20: Tyler | D20: Aguirre | E20: =CONCATENATE(C20," ",D20) -> Tyler Aguirre | F20: =PROPER(E20) -> Tyler Aguirre | H20: Male | I20: =PROPER(H20) -> Male | J20: 56 | K20: =IF(ISBLANK(J20),ROUND(AVERAGEIF($I$2:$I$1001,I20,$J$2:$J$1001),0),J20) -> 56 | L20: =IF(AND(K20>=20,K20<=30),"First level",IF(AND(K20>30,K20<=40),"Second level",IF(AND(K20>40,K20<=50),"Third level",IF(H27>50,"Fourth level")))) -> Fourth level | M20: United States | N20: English | O20: UI/UX Design | P20: 31 | Q20: =IF(ISBLANK(P20),ROUND(AVERAGEIF($L$2:$L$1001,L20,$P$2:$P$1001),0),P20) -> 31 | R20: USD 50 | S20: 50 | T20: 50 | U20: =IF(ISBLANK(T20),AVERAGE(T19:T1019),T20) -> 50 | V20: 50 | W20: 1.1 | X20: =IF(ISBLANK(W20),AVERAGE(W20:W1019),W20) -> 1.1 | Y20: No | Z20: =CLEAN(TRIM(Y20)) -> No | AA20: =IF(ISBLANK(Z20),"Unknown",Z20) -> No | AB20: =PROPER(AA20) -> No | AC20: 75 | AD20: =IF(ISBLANK(AC20),AVERAGE(AC20:AC1019),AC20) -> 75 | AF20: After filled (Blank Columns):
A21: FL250020 | B21: Matthew Lawson | C21: Matthew | D21: Lawson | E21: =CONCATENATE(C21," ",D21) -> Matthew Lawson | F21: =PROPER(E21) -> Matthew Lawson | H21: Male | I21: =PROPER(H21) -> Male | J21: 57 | K21: =IF(ISBLANK(J21),ROUND(AVERAGEIF($I$2:$I$1001,I21,$J$2:$J$1001),0),J21) -> 57 | L21: =IF(AND(K21>=20,K21<=30),"First level",IF(AND(K21>30,K21<=40),"Second level",IF(AND(K21>40,K21<=50),"Third level",IF(H28>50,"Fourth level")))) -> Fourth level | M21: Italy | N21: Italian | O21: Web Development | P21: 3 | Q21: =IF(ISBLANK(P21),ROUND(AVERAGEIF($L$2:$L$1001,L21,$P$2:$P$1001),0),P21) -> 3 | R21: USD 100 | S21: 100 | T21: 100 | U21: =IF(ISBLANK(T21),AVERAGE(T20:T1020),T21) -> 100 | V21: 100 | W21: 1.8 | X21: =IF(ISBLANK(W21),AVERAGE(W21:W1020),W21) -> 1.8 | Y21: yes | Z21: =CLEAN(TRIM(Y21)) -> yes | AA21: =IF(ISBLANK(Z21),"Unknown",Z21) -> yes | AB21: =PROPER(AA21) -> Yes | AC21: 68 | AD21: =IF(ISBLANK(AC21),AVERAGE(AC21:AC1020),AC21) -> 68 | AF21: freelancer_ID | AG21: =COUNTBLANK($A$2:$A$1001) -> 0
A22: FL250021 | B22: James Cherry | C22: James | D22: Cherry | E22: =CONCATENATE(C22," ",D22) -> James Cherry | F22: =PROPER(E22) -> James Cherry | H22: Male | I22: =PROPER(H22) -> Male | K22: =IF(ISBLANK(J22),ROUND(AVERAGEIF($I$2:$I$1001,I22,$J$2:$J$1001),0),J22) -> 41 | L22: =IF(AND(K22>=20,K22<=30),"First level",IF(AND(K22>30,K22<=40),"Second level",IF(AND(K22>40,K22<=50),"Third level",IF(H29>50,"Fourth level")))) -> Third level | M22: Indonesia | N22: Indonesian | O22: AI | P22: 9 | Q22: =IF(ISBLANK(P22),ROUND(AVERAGEIF($L$2:$L$1001,L22,$P$2:$P$1001),0),P22) -> 9 | R22: 50 | S22: 50 | T22: 50 | U22: =IF(ISBLANK(T22),AVERAGE(T21:T1021),T22) -> 50 | V22: 50 | W22: 1.8 | X22: =IF(ISBLANK(W22),AVERAGE(W22:W1021),W22) -> 1.8 | Y22: No | Z22: =CLEAN(TRIM(Y22)) -> No | AA22: =IF(ISBLANK(Z22),"Unknown",Z22) -> No | AB22: =PROPER(AA22) -> No | AC22: 65 | AD22: =IF(ISBLANK(AC22),AVERAGE(AC22:AC1021),AC22) -> 65 | AF22: name | AG22: =COUNTBLANK($B$2:$B$1001) -> 0
A23: FL250022 | B23: Samuel Sanford | C23: Samuel | D23: Sanford | E23: =CONCATENATE(C23," ",D23) -> Samuel Sanford | F23: =PROPER(E23) -> Samuel Sanford | H23: Male | I23: =PROPER(H23) -> Male | J23: 51 | K23: =IF(ISBLANK(J23),ROUND(AVERAGEIF($I$2:$I$1001,I23,$J$2:$J$1001),0),J23) -> 51 | L23: =IF(AND(K23>=20,K23<=30),"First level",IF(AND(K23>30,K23<=40),"Second level",IF(AND(K23>40,K23<=50),"Third level",IF(H30>50,"Fourth level")))) -> Fourth level | M23: Japan | N23: Japanese | O23: DevOps | Q23: =IF(ISBLANK(P23),ROUND(AVERAGEIF($L$2:$L$1001,L23,$P$2:$P$1001),0),P23) -> 19 | U23: =IF(ISBLANK(T23),AVERAGE(T22:T1022),T23) -> 52.376404 | V23: 52.376404 | W23: 2.4 | X23: =IF(ISBLANK(W23),AVERAGE(W23:W1022),W23) -> 2.4 | Y23: No | Z23: =CLEAN(TRIM(Y23)) -> No | AA23: =IF(ISBLANK(Z23),"Unknown",Z23) -> No | AB23: =PROPER(AA23) -> No | AC23: 69 | AD23: =IF(ISBLANK(AC23),AVERAGE(AC23:AC1022),AC23) -> 69 | AF23: gender | AG23: =COUNTBLANK($H$2:$H$1001) -> 0
A24: FL250023 | B24: Cesar Greene | C24: Cesar | D24: Greene | E24: =CONCATENATE(C24," ",D24) -> Cesar Greene | F24: =PROPER(E24) -> Cesar Greene | H24: Male | I24: =PROPER(H24) -> Male | J24: 51 | K24: =IF(ISBLANK(J24),ROUND(AVERAGEIF($I$2:$I$1001,I24,$J$2:$J$1001),0),J24) -> 51 | L24: =IF(AND(K24>=20,K24<=30),"First level",IF(AND(K24>30,K24<=40),"Second level",IF(AND(K24>40,K24<=50),"Third level",IF(H31>50,"Fourth level")))) -> Fourth level | M24: Brazil | N24: Portuguese | O24: Cybersecurity | P24: 21 | Q24: =IF(ISBLANK(P24),ROUND(AVERAGEIF($L$2:$L$1001,L24,$P$2:$P$1001),0),P24) -> 21 | R24: USD 30 | S24: 30 | T24: 30 | U24: =IF(ISBLANK(T24),AVERAGE(T23:T1023),T24) -> 30 | V24: 30 | W24: 4.7 | X24: =IF(ISBLANK(W24),AVERAGE(W24:W1023),W24) -> 4.7 | Y24: No | Z24: =CLEAN(TRIM(Y24)) -> No | AA24: =IF(ISBLANK(Z24),"Unknown",Z24) -> No | AB24: =PROPER(AA24) -> No | AD24: =IF(ISBLANK(AC24),AVERAGE(AC24:AC1023),AC24) -> 79.280745 | AF24: age | AG24: =COUNTBLANK($K$2:$K$1001) -> 0
A25: FL250024 | B25: Melanie Carter | C25: Melanie | D25: Carter | E25: =CONCATENATE(C25," ",D25) -> Melanie Carter | F25: =PROPER(E25) -> Melanie Carter | H25: female | I25: =PROPER(H25) -> Female | J25: 51 | K25: =IF(ISBLANK(J25),ROUND(AVERAGEIF($I$2:$I$1001,I25,$J$2:$J$1001),0),J25) -> 51 | L25: =IF(AND(K25>=20,K25<=30),"First level",IF(AND(K25>30,K25<=40),"Second level",IF(AND(K25>40,K25<=50),"Third level",IF(H32>50,"Fourth level")))) -> Fourth level | M25: South Korea | N25: Korean | O25: Machine Learning | P25: 15 | Q25: =IF(ISBLANK(P25),ROUND(AVERAGEIF($L$2:$L$1001,L25,$P$2:$P$1001),0),P25) -> 15 | R25: $50 | S25: $50 | T25: 50 | U25: =IF(ISBLANK(T25),AVERAGE(T24:T1024),T25) -> 50 | V25: 50 | W25: 1.3 | X25: =IF(ISBLANK(W25),AVERAGE(W25:W1024),W25) -> 1.3 | Y25: Yes | Z25: =CLEAN(TRIM(Y25)) -> Yes | AA25: =IF(ISBLANK(Z25),"Unknown",Z25) -> Yes | AB25: =PROPER(AA25) -> Yes | AC25: 100 | AD25: =IF(ISBLANK(AC25),AVERAGE(AC25:AC1024),AC25) -> 100 | AF25: country | AG25: =COUNTBLANK($M$2:$M$1001) -> 0
A26: FL250025 | B26: Jennifer Martin | C26: Jennifer | D26: Martin | E26: =CONCATENATE(C26," ",D26) -> Jennifer Martin | F26: =PROPER(E26) -> Jennifer Martin | H26: Female | I26: =PROPER(H26) -> Female | J26: 54 | K26: =IF(ISBLANK(J26),ROUND(AVERAGEIF($I$2:$I$1001,I26,$J$2:$J$1001),0),J26) -> 54 | L26: =IF(AND(K26>=20,K26<=30),"First level",IF(AND(K26>30,K26<=40),"Second level",IF(AND(K26>40,K26<=50),"Third level",IF(H33>50,"Fourth level")))) -> Fourth level | M26: Indonesia | N26: Indonesian | O26: Machine Learning | P26: 13 | Q26: =IF(ISBLANK(P26),ROUND(AVERAGEIF($L$2:$L$1001,L26,$P$2:$P$1001),0),P26) -> 13 | R26: 75 | S26: 75 | T26: 75 | U26: =IF(ISBLANK(T26),AVERAGE(T25:T1025),T26) -> 75 | V26: 75 | W26: 2.9 | X26: =IF(ISBLANK(W26),AVERAGE(W26:W1025),W26) -> 2.9 | AA26: =IF(ISBLANK(Z26),"Unknown",Z26) -> Unknown | AB26: =PROPER(AA26) -> Unknown | AC26: 92 | AD26: =IF(ISBLANK(AC26),AVERAGE(AC26:AC1025),AC26) -> 92 | AF26: language | AG26: =COUNTBLANK($N$2:$N$1001) -> 0
A27: FL250026 | B27: Anna Mccann | C27: Anna | D27: Mccann | E27: =CONCATENATE(C27," ",D27) -> Anna Mccann | F27: =PROPER(E27) -> Anna Mccann | H27: FEMALE | I27: =PROPER(H27) -> Female | J27: 22 | K27: =IF(ISBLANK(J27),ROUND(AVERAGEIF($I$2:$I$1001,I27,$J$2:$J$1001),0),J27) -> 22 | L27: =IF(AND(K27>=20,K27<=30),"First level",IF(AND(K27>30,K27<=40),"Second level",IF(AND(K27>40,K27<=50),"Third level",IF(H34>50,"Fourth level")))) -> First level | M27: South Korea | N27: Korean | O27: DevOps | P27: 0 | Q27: =IF(ISBLANK(P27),ROUND(AVERAGEIF($L$2:$L$1001,L27,$P$2:$P$1001),0),P27) -> 0 | R27: USD 30 | S27: 30 | T27: 30 | U27: =IF(ISBLANK(T27),AVERAGE(T26:T1026),T27) -> 30 | V27: 30 | W27: 1.2 | X27: =IF(ISBLANK(W27),AVERAGE(W27:W1026),W27) -> 1.2 | Y27: Yes | Z27: =CLEAN(TRIM(Y27)) -> Yes | AA27: =IF(ISBLANK(Z27),"Unknown",Z27) -> Yes | AB27: =PROPER(AA27) -> Yes | AC27: 70 | AD27: =IF(ISBLANK(AC27),AVERAGE(AC27:AC1026),AC27) -> 70 | AF27: primary_skill | AG27: =COUNTBLANK($O$2:$O$1001) -> 0
A28: FL250027 | B28: Marissa Bass | C28: Marissa | D28: Bass | E28: =CONCATENATE(C28," ",D28) -> Marissa Bass | F28: =PROPER(E28) -> Marissa Bass | H28: female | I28: =PROPER(H28) -> Female | J28: 34 | K28: =IF(ISBLANK(J28),ROUND(AVERAGEIF($I$2:$I$1001,I28,$J$2:$J$1001),0),J28) -> 34 | L28: =IF(AND(K28>=20,K28<=30),"First level",IF(AND(K28>30,K28<=40),"Second level",IF(AND(K28>40,K28<=50),"Third level",IF(H35>50,"Fourth level")))) -> Second level | M28: Japan | N28: Japanese | O28: Blockchain Development | P28: 8 | Q28: =IF(ISBLANK(P28),ROUND(AVERAGEIF($L$2:$L$1001,L28,$P$2:$P$1001),0),P28) -> 8 | R28: $20 | S28: $20 | T28: 20 | U28: =IF(ISBLANK(T28),AVERAGE(T27:T1027),T28) -> 20 | V28: 20 | W28: 0 | X28: =IF(ISBLANK(W28),AVERAGE(W28:W1027),W28) -> 0 | Y28: Yes | Z28: =CLEAN(TRIM(Y28)) -> Yes | AA28: =IF(ISBLANK(Z28),"Unknown",Z28) -> Yes | AB28: =PROPER(AA28) -> Yes | AC28: 89 | AD28: =IF(ISBLANK(AC28),AVERAGE(AC28:AC1027),AC28) -> 89 | AF28: years_of_experience | AG28: =COUNTBLANK($Q$2:$Q$1001) -> 0
A29: FL250028 | B29: Alexis Day | C29: Alexis | D29: Day | E29: =CONCATENATE(C29," ",D29) -> Alexis Day | F29: =PROPER(E29) -> Alexis Day | H29: Female | I29: =PROPER(H29) -> Female | J29: 36 | K29: =IF(ISBLANK(J29),ROUND(AVERAGEIF($I$2:$I$1001,I29,$J$2:$J$1001),0),J29) -> 36 | L29: =IF(AND(K29>=20,K29<=30),"First level",IF(AND(K29>30,K29<=40),"Second level",IF(AND(K29>40,K29<=50),"Third level",IF(H36>50,"Fourth level")))) -> Second level | M29: Russia | N29: Russian | O29: Graphic Design | P29: 11 | Q29: =IF(ISBLANK(P29),ROUND(AVERAGEIF($L$2:$L$1001,L29,$P$2:$P$1001),0),P29) -> 11 | U29: =IF(ISBLANK(T29),AVERAGE(T28:T1028),T29) -> 52.40678 | V29: 52.40678 | W29: 1.8 | X29: =IF(ISBLANK(W29),AVERAGE(W29:W1028),W29) -> 1.8 | Y29: Yes | Z29: =CLEAN(TRIM(Y29)) -> Yes | AA29: =IF(ISBLANK(Z29),"Unknown",Z29) -> Yes | AB29: =PROPER(AA29) -> Yes | AC29: 86 | AD29: =IF(ISBLANK(AC29),AVERAGE(AC29:AC1028),AC29) -> 86 | AF29: hourly_rate (USD) | AG29: =COUNTBLANK($V$2:$V$1001) -> 0
A30: FL250029 | B30: Megan Jones | C30: Megan | D30: Jones | E30: =CONCATENATE(C30," ",D30) -> Megan Jones | F30: =PROPER(E30) -> Megan Jones | H30: female | I30: =PROPER(H30) -> Female | J30: 47 | K30: =IF(ISBLANK(J30),ROUND(AVERAGEIF($I$2:$I$1001,I30,$J$2:$J$1001),0),J30) -> 47 | L30: =IF(AND(K30>=20,K30<=30),"First level",IF(AND(K30>30,K30<=40),"Second level",IF(AND(K30>40,K30<=50),"Third level",IF(H37>50,"Fourth level")))) -> Third level | M30: Canada | N30: English | O30: AI | P30: 22 | Q30: =IF(ISBLANK(P30),ROUND(AVERAGEIF($L$2:$L$1001,L30,$P$2:$P$1001),0),P30) -> 22 | R30: 30 | S30: 30 | T30: 30 | U30: =IF(ISBLANK(T30),AVERAGE(T29:T1029),T30) -> 30 | V30: 30 | W30: 1.3 | X30: =IF(ISBLANK(W30),AVERAGE(W30:W1029),W30) -> 1.3 | Y30: No | Z30: =CLEAN(TRIM(Y30)) -> No | AA30: =IF(ISBLANK(Z30),"Unknown",Z30) -> No | AB30: =PROPER(AA30) -> No | AC30: 62 | AD30: =IF(ISBLANK(AC30),AVERAGE(AC30:AC1029),AC30) -> 62 | AF30: rating | AG30: =COUNTBLANK($X$2:$X$1001) -> 0
A31: FL250030 | B31: Lori Smith | C31: Lori | D31: Smith | E31: =CONCATENATE(C31," ",D31) -> Lori Smith | F31: =PROPER(E31) -> Lori Smith | H31: FEMALE | I31: =PROPER(H31) -> Female | J31: 41 | K31: =IF(ISBLANK(J31),ROUND(AVERAGEIF($I$2:$I$1001,I31,$J$2:$J$1001),0),J31) -> 41 | L31: =IF(AND(K31>=20,K31<=30),"First level",IF(AND(K31>30,K31<=40),"Second level",IF(AND(K31>40,K31<=50),"Third level",IF(H38>50,"Fourth level")))) -> Third level | M31: Netherlands | N31: Dutch | O31: Data Analysis | P31: 14 | Q31: =IF(ISBLANK(P31),ROUND(AVERAGEIF($L$2:$L$1001,L31,$P$2:$P$1001),0),P31) -> 14 | R31: USD 75 | S31: 75 | T31: 75 | U31: =IF(ISBLANK(T31),AVERAGE(T30:T1030),T31) -> 75 | V31: 75 | W31: 1.2 | X31: =IF(ISBLANK(W31),AVERAGE(W31:W1030),W31) -> 1.2 | Y31: No | Z31: =CLEAN(TRIM(Y31)) -> No | AA31: =IF(ISBLANK(Z31),"Unknown",Z31) -> No | AB31: =PROPER(AA31) -> No | AD31: =IF(ISBLANK(AC31),AVERAGE(AC31:AC1030),AC31) -> 79.251564 | AF31: is_active | AG31: =COUNTBLANK($AA$2:$AA$1001) -> 0
A32: FL250031 | B32: Eric Carpenter | C32: Eric | D32: Carpenter | E32: =CONCATENATE(C32," ",D32) -> Eric Carpenter | F32: =PROPER(E32) -> Eric Carpenter | H32: Male | I32: =PROPER(H32) -> Male | J32: 22 | K32: =IF(ISBLANK(J32),ROUND(AVERAGEIF($I$2:$I$1001,I32,$J$2:$J$1001),0),J32) -> 22 | L32: =IF(AND(K32>=20,K32<=30),"First level",IF(AND(K32>30,K32<=40),"Second level",IF(AND(K32>40,K32<=50),"Third level",IF(H39>50,"Fourth level")))) -> First level | M32: Netherlands | N32: Dutch | O32: DevOps | P32: 4 | Q32: =IF(ISBLANK(P32),ROUND(AVERAGEIF($L$2:$L$1001,L32,$P$2:$P$1001),0),P32) -> 4 | U32: =IF(ISBLANK(T32),AVERAGE(T31:T1031),T32) -> 52.468856 | V32: 52.468856 | W32: 1 | X32: =IF(ISBLANK(W32),AVERAGE(W32:W1031),W32) -> 1 | Y32: yes | Z32: =CLEAN(TRIM(Y32)) -> yes | AA32: =IF(ISBLANK(Z32),"Unknown",Z32) -> yes | AB32: =PROPER(AA32) -> Yes | AD32: =IF(ISBLANK(AC32),AVERAGE(AC32:AC1031),AC32) -> 79.251564 | AF32: client_satisfaction | AG32: =COUNTBLANK(AD1:AD1001) -> 0
A33: FL250032 | B33: Timothy Daniels | C33: Timothy | D33: Daniels | E33: =CONCATENATE(C33," ",D33) -> Timothy Daniels | F33: =PROPER(E33) -> Timothy Daniels | H33: Male | I33: =PROPER(H33) -> Male | J33: 38 | K33: =IF(ISBLANK(J33),ROUND(AVERAGEIF($I$2:$I$1001,I33,$J$2:$J$1001),0),J33) -> 38 | L33: =IF(AND(K33>=20,K33<=30),"First level",IF(AND(K33>30,K33<=40),"Second level",IF(AND(K33>40,K33<=50),"Third level",IF(H40>50,"Fourth level")))) -> Second level | M33: France | N33: French | O33: Machine Learning | P33: 19 | Q33: =IF(ISBLANK(P33),ROUND(AVERAGEIF($L$2:$L$1001,L33,$P$2:$P$1001),0),P33) -> 19 | R33: USD 100 | S33: 100 | T33: 100 | U33: =IF(ISBLANK(T33),AVERAGE(T32:T1032),T33) -> 100 | V33: 100 | W33: 4.2 | X33: =IF(ISBLANK(W33),AVERAGE(W33:W1032),W33) -> 4.2 | Y33: No | Z33: =CLEAN(TRIM(Y33)) -> No | AA33: =IF(ISBLANK(Z33),"Unknown",Z33) -> No | AB33: =PROPER(AA33) -> No | AC33: 68 | AD33: =IF(ISBLANK(AC33),AVERAGE(AC33:AC1032),AC33) -> 68
A34: FL250033 | B34: Robert Nelson | C34: Robert | D34: Nelson | E34: =CONCATENATE(C34," ",D34) -> Robert Nelson | F34: =PROPER(E34) -> Robert Nelson | H34: Male | I34: =PROPER(H34) -> Male | J34: 46 | K34: =IF(ISBLANK(J34),ROUND(AVERAGEIF($I$2:$I$1001,I34,$J$2:$J$1001),0),J34) -> 46 | L34: =IF(AND(K34>=20,K34<=30),"First level",IF(AND(K34>30,K34<=40),"Second level",IF(AND(K34>40,K34<=50),"Third level",IF(H41>50,"Fourth level")))) -> Third level | M34: Egypt | N34: Arabic | O34: AI | P34: 9 | Q34: =IF(ISBLANK(P34),ROUND(AVERAGEIF($L$2:$L$1001,L34,$P$2:$P$1001),0),P34) -> 9 | R34: 20 | S34: 20 | T34: 20 | U34: =IF(ISBLANK(T34),AVERAGE(T33:T1033),T34) -> 20 | V34: 20 | W34: 1.4 | X34: =IF(ISBLANK(W34),AVERAGE(W34:W1033),W34) -> 1.4 | Y34: Yes | Z34: =CLEAN(TRIM(Y34)) -> Yes | AA34: =IF(ISBLANK(Z34),"Unknown",Z34) -> Yes | AB34: =PROPER(AA34) -> Yes | AC34: 76 | AD34: =IF(ISBLANK(AC34),AVERAGE(AC34:AC1033),AC34) -> 76
A35: FL250034 | B35: Michael Anderson | C35: Michael | D35: Anderson | E35: =CONCATENATE(C35," ",D35) -> Michael Anderson | F35: =PROPER(E35) -> Michael Anderson | H35: male | I35: =PROPER(H35) -> Male | K35: =IF(ISBLANK(J35),ROUND(AVERAGEIF($I$2:$I$1001,I35,$J$2:$J$1001),0),J35) -> 41 | L35: =IF(AND(K35>=20,K35<=30),"First level",IF(AND(K35>30,K35<=40),"Second level",IF(AND(K35>40,K35<=50),"Third level",IF(H42>50,"Fourth level")))) -> Third level | M35: South Korea | N35: Korean | O35: AI | P35: 9 | Q35: =IF(ISBLANK(P35),ROUND(AVERAGEIF($L$2:$L$1001,L35,$P$2:$P$1001),0),P35) -> 9 | R35: 40 | S35: 40 | T35: 40 | U35: =IF(ISBLANK(T35),AVERAGE(T34:T1034),T35) -> 40 | V35: 40 | W35: 2.4 | X35: =IF(ISBLANK(W35),AVERAGE(W35:W1034),W35) -> 2.4 | Y35: yes | Z35: =CLEAN(TRIM(Y35)) -> yes | AA35: =IF(ISBLANK(Z35),"Unknown",Z35) -> yes | AB35: =PROPER(AA35) -> Yes | AC35: 82 | AD35: =IF(ISBLANK(AC35),AVERAGE(AC35:AC1034),AC35) -> 82
A36: FL250035 | B36: Jessica Snyder | C36: Jessica | D36: Snyder | E36: =CONCATENATE(C36," ",D36) -> Jessica Snyder | F36: =PROPER(E36) -> Jessica Snyder | H36: FEMALE | I36: =PROPER(H36) -> Female | J36: 54 | K36: =IF(ISBLANK(J36),ROUND(AVERAGEIF($I$2:$I$1001,I36,$J$2:$J$1001),0),J36) -> 54 | L36: =IF(AND(K36>=20,K36<=30),"First level",IF(AND(K36>30,K36<=40),"Second level",IF(AND(K36>40,K36<=50),"Third level",IF(H43>50,"Fourth level")))) -> Fourth level | M36: United States | N36: English | O36: Web Development | P36: 32 | Q36: =IF(ISBLANK(P36),ROUND(AVERAGEIF($L$2:$L$1001,L36,$P$2:$P$1001),0),P36) -> 32 | R36: 75 | S36: 75 | T36: 75 | U36: =IF(ISBLANK(T36),AVERAGE(T35:T1035),T36) -> 75 | V36: 75 | W36: 1 | X36: =IF(ISBLANK(W36),AVERAGE(W36:W1035),W36) -> 1 | Y36: yes | Z36: =CLEAN(TRIM(Y36)) -> yes | AA36: =IF(ISBLANK(Z36),"Unknown",Z36) -> yes | AB36: =PROPER(AA36) -> Yes | AC36: 81 | AD36: =IF(ISBLANK(AC36),AVERAGE(AC36:AC1035),AC36) -> 81
A37: FL250036 | B37: Emily Daniels | C37: Emily | D37: Daniels | E37: =CONCATENATE(C37," ",D37) -> Emily Daniels | F37: =PROPER(E37) -> Emily Daniels | H37: female | I37: =PROPER(H37) -> Female | J37: 52 | K37: =IF(ISBLANK(J37),ROUND(AVERAGEIF($I$2:$I$1001,I37,$J$2:$J$1001),0),J37) -> 52 | L37: =IF(AND(K37>=20,K37<=30),"First level",IF(AND(K37>30,K37<=40),"Second level",IF(AND(K37>40,K37<=50),"Third level",IF(H44>50,"Fourth level")))) -> Fourth level | M37: South Korea | N37: Korean | O37: Web Development | P37: 28 | Q37: =IF(ISBLANK(P37),ROUND(AVERAGEIF($L$2:$L$1001,L37,$P$2:$P$1001),0),P37) -> 28 | R37: $20 | S37: $20 | T37: 20 | U37: =IF(ISBLANK(T37),AVERAGE(T36:T1036),T37) -> 20 | V37: 20 | X37: =IF(ISBLANK(W37),AVERAGE(W37:W1036),W37) -> 2.5203917 | Y37: No | Z37: =CLEAN(TRIM(Y37)) -> No | AA37: =IF(ISBLANK(Z37),"Unknown",Z37) -> No | AB37: =PROPER(AA37) -> No | AD37: =IF(ISBLANK(AC37),AVERAGE(AC37:AC1036),AC37) -> 79.264151
A38: FL250037 | B38: Jamie Ramirez | C38: Jamie | D38: Ramirez | E38: =CONCATENATE(C38," ",D38) -> Jamie Ramirez | F38: =PROPER(E38) -> Jamie Ramirez | H38: Female | I38: =PROPER(H38) -> Female | J38: 42 | K38: =IF(ISBLANK(J38),ROUND(AVERAGEIF($I$2:$I$1001,I38,$J$2:$J$1001),0),J38) -> 42 | L38: =IF(AND(K38>=20,K38<=30),"First level",IF(AND(K38>30,K38<=40),"Second level",IF(AND(K38>40,K38<=50),"Third level",IF(H45>50,"Fourth level")))) -> Third level | M38: Japan | N38: Japanese | O38: Mobile Apps | P38: 6 | Q38: =IF(ISBLANK(P38),ROUND(AVERAGEIF($L$2:$L$1001,L38,$P$2:$P$1001),0),P38) -> 6 | R38: 40 | S38: 40 | T38: 40 | U38: =IF(ISBLANK(T38),AVERAGE(T37:T1037),T38) -> 40 | V38: 40 | X38: =IF(ISBLANK(W38),AVERAGE(W38:W1037),W38) -> 2.5203917 | Y38: No | Z38: =CLEAN(TRIM(Y38)) -> No | AA38: =IF(ISBLANK(Z38),"Unknown",Z38) -> No | AB38: =PROPER(AA38) -> No | AC38: 63 | AD38: =IF(ISBLANK(AC38),AVERAGE(AC38:AC1037),AC38) -> 63
A39: FL250038 | B39: Amy Harrison | C39: Amy | D39: Harrison | E39: =CONCATENATE(C39," ",D39) -> Amy Harrison | F39: =PROPER(E39) -> Amy Harrison | H39: Female | I39: =PROPER(H39) -> Female | J39: 29 | K39: =IF(ISBLANK(J39),ROUND(AVERAGEIF($I$2:$I$1001,I39,$J$2:$J$1001),0),J39) -> 29 | L39: =IF(AND(K39>=20,K39<=30),"First level",IF(AND(K39>30,K39<=40),"Second level",IF(AND(K39>40,K39<=50),"Third level",IF(H46>50,"Fourth level")))) -> First level | M39: Netherlands | N39: Dutch | O39: Graphic Design | P39: 10 | Q39: =IF(ISBLANK(P39),ROUND(AVERAGEIF($L$2:$L$1001,L39,$P$2:$P$1001),0),P39) -> 10 | R39: 40 | S39: 40 | T39: 40 | U39: =IF(ISBLANK(T39),AVERAGE(T38:T1038),T39) -> 40 | V39: 40 | W39: 2.2 | X39: =IF(ISBLANK(W39),AVERAGE(W39:W1038),W39) -> 2.2 | Y39: No | Z39: =CLEAN(TRIM(Y39)) -> No | AA39: =IF(ISBLANK(Z39),"Unknown",Z39) -> No | AB39: =PROPER(AA39) -> No | AC39: 67 | AD39: =IF(ISBLANK(AC39),AVERAGE(AC39:AC1038),AC39) -> 67
A40: FL250039 | B40: Melinda White | C40: Melinda | D40: White | E40: =CONCATENATE(C40," ",D40) -> Melinda White | F40: =PROPER(E40) -> Melinda White | H40: Female | I40: =PROPER(H40) -> Female | J40: 42 | K40: =IF(ISBLANK(J40),ROUND(AVERAGEIF($I$2:$I$1001,I40,$J$2:$J$1001),0),J40) -> 42 | L40: =IF(AND(K40>=20,K40<=30),"First level",IF(AND(K40>30,K40<=40),"Second level",IF(AND(K40>40,K40<=50),"Third level",IF(H47>50,"Fourth level")))) -> Third level | M40: South Africa | N40: Afrikaans | O40: Mobile Apps | P40: 23 | Q40: =IF(ISBLANK(P40),ROUND(AVERAGEIF($L$2:$L$1001,L40,$P$2:$P$1001),0),P40) -> 23 | R40: 50 | S40: 50 | T40: 50 | U40: =IF(ISBLANK(T40),AVERAGE(T39:T1039),T40) -> 50 | V40: 50 | W40: 3.2 | X40: =IF(ISBLANK(W40),AVERAGE(W40:W1039),W40) -> 3.2 | Y40: yes | Z40: =CLEAN(TRIM(Y40)) -> yes | AA40: =IF(ISBLANK(Z40),"Unknown",Z40) -> yes | AB40: =PROPER(AA40) -> Yes | AD40: =IF(ISBLANK(AC40),AVERAGE(AC40:AC1039),AC40) -> 79.300126
...

Sheet Cleaned Data
A1: freelancer_ID | B1: name | C1: gender | D1: age | E1: country | F1: language | G1: primary_skill | H1: years_of_experience | I1: hourly_rate (USD) | J1: rating | K1: is_active | L1: client_satisfaction
A2: FL250630 | B2: =VLOOKUP(A2,Sheet1!A:E,5,0) -> Angela Blackwell | C2: =VLOOKUP(A2,Sheet1!A:I,9,0) -> Female | D2: =VLOOKUP(A2,Sheet1!A:K,11,0) -> 60 | E2: =VLOOKUP(A2,Sheet1!A:M,13,0) -> Turkey | F2: =VLOOKUP(A2,Sheet1!A:N,14,0) -> Turkish | G2: =VLOOKUP(A2,Sheet1!A:O,15,0) -> Web Development | H2: =VLOOKUP(A2,Sheet1!A:Q,17,0) -> 41 | I2: =VLOOKUP(A2,Sheet1!A:V,22,0) -> 40 | J2: =VLOOKUP(A2,Sheet1!A:X,24,0) -> 4.9 | K2: =VLOOKUP(A2,Sheet1!A:AB,28,0) -> Yes | L2: =VLOOKUP(A2,Sheet1!A:AD,30,0) -> 66
A3: FL250279 | B3: =VLOOKUP(A3,Sheet1!A:E,5,0) -> Anthony Goodwin | C3: =VLOOKUP(A3,Sheet1!A:I,9,0) -> Male | D3: =VLOOKUP(A3,Sheet1!A:K,11,0) -> 60 | E3: =VLOOKUP(A3,Sheet1!A:M,13,0) -> Turkey | F3: =VLOOKUP(A3,Sheet1!A:N,14,0) -> Turkish | G3: =VLOOKUP(A3,Sheet1!A:O,15,0) -> Data Analysis | H3: =VLOOKUP(A3,Sheet1!A:Q,17,0) -> 6 | I3: =VLOOKUP(A3,Sheet1!A:V,22,0) -> 52.435312 | J3: =VLOOKUP(A3,Sheet1!A:X,24,0) -> 3.2 | K3: =VLOOKUP(A3,Sheet1!A:AB,28,0) -> No | L3: =VLOOKUP(A3,Sheet1!A:AD,30,0) -> 95
A4: FL250169 | B4: =VLOOKUP(A4,Sheet1!A:E,5,0) -> Anthony Larsen | C4: =VLOOKUP(A4,Sheet1!A:I,9,0) -> Male | D4: =VLOOKUP(A4,Sheet1!A:K,11,0) -> 60 | E4: =VLOOKUP(A4,Sheet1!A:M,13,0) -> Argentina | F4: =VLOOKUP(A4,Sheet1!A:N,14,0) -> Spanish | G4: =VLOOKUP(A4,Sheet1!A:O,15,0) -> Cybersecurity | H4: =VLOOKUP(A4,Sheet1!A:Q,17,0) -> 20 | I4: =VLOOKUP(A4,Sheet1!A:V,22,0) -> 40 | J4: =VLOOKUP(A4,Sheet1!A:X,24,0) -> 1.4 | K4: =VLOOKUP(A4,Sheet1!A:AB,28,0) -> No | L4: =VLOOKUP(A4,Sheet1!A:AD,30,0) -> 87
A5: FL250986 | B5: =VLOOKUP(A5,Sheet1!A:E,5,0) -> Bradley Wu | C5: =VLOOKUP(A5,Sheet1!A:I,9,0) -> Male | D5: =VLOOKUP(A5,Sheet1!A:K,11,0) -> 60 | E5: =VLOOKUP(A5,Sheet1!A:M,13,0) -> Spain | F5: =VLOOKUP(A5,Sheet1!A:N,14,0) -> Spanish | G5: =VLOOKUP(A5,Sheet1!A:O,15,0) -> Blockchain Development | H5: =VLOOKUP(A5,Sheet1!A:Q,17,0) -> 39 | I5: =VLOOKUP(A5,Sheet1!A:V,22,0) -> 20 | J5: =VLOOKUP(A5,Sheet1!A:X,24,0) -> 1.4 | K5: =VLOOKUP(A5,Sheet1!A:AB,28,0) -> Yes | L5: =VLOOKUP(A5,Sheet1!A:AD,30,0) -> 86
A6: FL250862 | B6: =VLOOKUP(A6,Sheet1!A:E,5,0) -> Christopher Johnson | C6: =VLOOKUP(A6,Sheet1!A:I,9,0) -> Male | D6: =VLOOKUP(A6,Sheet1!A:K,11,0) -> 60 | E6: =VLOOKUP(A6,Sheet1!A:M,13,0) -> Japan | F6: =VLOOKUP(A6,Sheet1!A:N,14,0) -> Japanese | G6: =VLOOKUP(A6,Sheet1!A:O,15,0) -> AI | H6: =VLOOKUP(A6,Sheet1!A:Q,17,0) -> 19 | I6: =VLOOKUP(A6,Sheet1!A:V,22,0) -> 20 | J6: =VLOOKUP(A6,Sheet1!A:X,24,0) -> 2.2 | K6: =VLOOKUP(A6,Sheet1!A:AB,28,0) -> No | L6: =VLOOKUP(A6,Sheet1!A:AD,30,0) -> 60
A7: FL250225 | B7: =VLOOKUP(A7,Sheet1!A:E,5,0) -> Darrell Johnson | C7: =VLOOKUP(A7,Sheet1!A:I,9,0) -> Male | D7: =VLOOKUP(A7,Sheet1!A:K,11,0) -> 60 | E7: =VLOOKUP(A7,Sheet1!A:M,13,0) -> Canada | F7: =VLOOKUP(A7,Sheet1!A:N,14,0) -> English | G7: =VLOOKUP(A7,Sheet1!A:O,15,0) -> Machine Learning | H7: =VLOOKUP(A7,Sheet1!A:Q,17,0) -> 3 | I7: =VLOOKUP(A7,Sheet1!A:V,22,0) -> 40 | J7: =VLOOKUP(A7,Sheet1!A:X,24,0) -> 4.7 | K7: =VLOOKUP(A7,Sheet1!A:AB,28,0) -> No | L7: =VLOOKUP(A7,Sheet1!A:AD,30,0) -> 63
A8: FL250333 | B8: =VLOOKUP(A8,Sheet1!A:E,5,0) -> Edwin Carter | C8: =VLOOKUP(A8,Sheet1!A:I,9,0) -> Male | D8: =VLOOKUP(A8,Sheet1!A:K,11,0) -> 60 | E8: =VLOOKUP(A8,Sheet1!A:M,13,0) -> United States | F8: =VLOOKUP(A8,Sheet1!A:N,14,0) -> English | G8: =VLOOKUP(A8,Sheet1!A:O,15,0) -> DevOps | H8: =VLOOKUP(A8,Sheet1!A:Q,17,0) -> 34 | I8: =VLOOKUP(A8,Sheet1!A:V,22,0) -> 52.397035 | J8: =VLOOKUP(A8,Sheet1!A:X,24,0) -> 2.5 | K8: =VLOOKUP(A8,Sheet1!A:AB,28,0) -> No | L8: =VLOOKUP(A8,Sheet1!A:AD,30,0) -> 93
A9: FL250070 | B9: =VLOOKUP(A9,Sheet1!A:E,5,0) -> Gina Thompson | C9: =VLOOKUP(A9,Sheet1!A:I,9,0) -> Female | D9: =VLOOKUP(A9,Sheet1!A:K,11,0) -> 60 | E9: =VLOOKUP(A9,Sheet1!A:M,13,0) -> China | F9: =VLOOKUP(A9,Sheet1!A:N,14,0) -> Mandarin | G9: =VLOOKUP(A9,Sheet1!A:O,15,0) -> UI/UX Design | H9: =VLOOKUP(A9,Sheet1!A:Q,17,0) -> 38 | I9: =VLOOKUP(A9,Sheet1!A:V,22,0) -> 20 | J9: =VLOOKUP(A9,Sheet1!A:X,24,0) -> 2 | K9: =VLOOKUP(A9,Sheet1!A:AB,28,0) -> No | L9: =VLOOKUP(A9,Sheet1!A:AD,30,0) -> 71
A10: FL250728 | B10: =VLOOKUP(A10,Sheet1!A:E,5,0) -> Ian Hayes | C10: =VLOOKUP(A10,Sheet1!A:I,9,0) -> Male | D10: =VLOOKUP(A10,Sheet1!A:K,11,0) -> 60 | E10: =VLOOKUP(A10,Sheet1!A:M,13,0) -> France | F10: =VLOOKUP(A10,Sheet1!A:N,14,0) -> French | G10: =VLOOKUP(A10,Sheet1!A:O,15,0) -> UI/UX Design | H10: =VLOOKUP(A10,Sheet1!A:Q,17,0) -> 0 | I10: =VLOOKUP(A10,Sheet1!A:V,22,0) -> 40 | J10: =VLOOKUP(A10,Sheet1!A:X,24,0) -> 4.9 | K10: =VLOOKUP(A10,Sheet1!A:AB,28,0) -> Yes | L10: =VLOOKUP(A10,Sheet1!A:AD,30,0) -> 68
A11: FL250040 | B11: =VLOOKUP(A11,Sheet1!A:E,5,0) -> James Hernandez | C11: =VLOOKUP(A11,Sheet1!A:I,9,0) -> Male | D11: =VLOOKUP(A11,Sheet1!A:K,11,0) -> 60 | E11: =VLOOKUP(A11,Sheet1!A:M,13,0) -> Japan | F11: =VLOOKUP(A11,Sheet1!A:N,14,0) -> Japanese | G11: =VLOOKUP(A11,Sheet1!A:O,15,0) -> Web Development | H11: =VLOOKUP(A11,Sheet1!A:Q,17,0) -> 13 | I11: =VLOOKUP(A11,Sheet1!A:V,22,0) -> 20 | J11: =VLOOKUP(A11,Sheet1!A:X,24,0) -> 3.6 | K11: =VLOOKUP(A11,Sheet1!A:AB,28,0) -> No | L11: =VLOOKUP(A11,Sheet1!A:AD,30,0) -> 80
A12: FL250727 | B12: =VLOOKUP(A12,Sheet1!A:E,5,0) -> John Castillo | C12: =VLOOKUP(A12,Sheet1!A:I,9,0) -> Male | D12: =VLOOKUP(A12,Sheet1!A:K,11,0) -> 60 | E12: =VLOOKUP(A12,Sheet1!A:M,13,0) -> Japan | F12: =VLOOKUP(A12,Sheet1!A:N,14,0) -> Japanese | G12: =VLOOKUP(A12,Sheet1!A:O,15,0) -> Data Analysis | H12: =VLOOKUP(A12,Sheet1!A:Q,17,0) -> 24 | I12: =VLOOKUP(A12,Sheet1!A:V,22,0) -> 40 | J12: =VLOOKUP(A12,Sheet1!A:X,24,0) -> 3.1 | K12: =VLOOKUP(A12,Sheet1!A:AB,28,0) -> No | L12: =VLOOKUP(A12,Sheet1!A:AD,30,0) -> 69
A13: FL250167 | B13: =VLOOKUP(A13,Sheet1!A:E,5,0) -> John Smith | C13: =VLOOKUP(A13,Sheet1!A:I,9,0) -> Male | D13: =VLOOKUP(A13,Sheet1!A:K,11,0) -> 60 | E13: =VLOOKUP(A13,Sheet1!A:M,13,0) -> South Korea | F13: =VLOOKUP(A13,Sheet1!A:N,14,0) -> Korean | G13: =VLOOKUP(A13,Sheet1!A:O,15,0) -> Mobile Apps | H13: =VLOOKUP(A13,Sheet1!A:Q,17,0) -> 33 | I13: =VLOOKUP(A13,Sheet1!A:V,22,0) -> 40 | J13: =VLOOKUP(A13,Sheet1!A:X,24,0) -> 3.6 | K13: =VLOOKUP(A13,Sheet1!A:AB,28,0) -> Yes | L13: =VLOOKUP(A13,Sheet1!A:AD,30,0) -> 87
... A1001: FL250825 | B1001: =VLOOKUP(A1001,Sheet1!A:E,5,0) -> William Harris | C1001: =VLOOKUP(A1001,Sheet1!A:I,9,0) -> Male | D1001: =VLOOKUP(A1001,Sheet1!A:K,11,0) -> 20 | E1001: =VLOOKUP(A1001,Sheet1!A:M,13,0) -> South Korea | F1001: =VLOOKUP(A1001,Sheet1!A:N,14,0) -> Korean | G1001: =VLOOKUP(A1001,Sheet1!A:O,15,0) -> AI | H1001: =VLOOKUP(A1001,Sheet1!A:Q,17,0) -> 1 | I1001: =VLOOKUP(A1001,Sheet1!A:V,22,0) -> 50 | J1001: =VLOOKUP(A1001,Sheet1!A:X,24,0) -> 2.3955696 | K1001: =VLOOKUP(A1001,Sheet1!A:AB,28,0) -> Yes | L1001: =VLOOKUP(A1001,Sheet1!A:AD,30,0) -> 81
